[2025-01-23 15:39:14] Traceback (most recent call last):
  File "/Users/yojunsmacbookprp/Documents/GitHub/PCSS/back/PCSS.py", line 156, in paper_crawl
    self.printStatus(f"{year} {conf} Crawling")
    ~~~~~~~~~~~~~~~~^^^^^^^^^^^^^^^^^^^^^^^^^^^
  File "/Users/yojunsmacbookprp/Documents/GitHub/PCSS/back/PCSS.py", line 271, in printStatus
    print(f'\r{msg} | paper: {len(self.CrawlData)}', end='')
    ~~~~~^^^^^^^^^^^^^^^^^^^^^^^^^^^^^^^^^^^^^^^^^^^^^^^^^^^
BrokenPipeError: [Errno 32] Broken pipe

[2025-01-23 15:39:14] Traceback (most recent call last):
  File "/Users/yojunsmacbookprp/Documents/GitHub/PCSS/back/PCSS.py", line 90, in paper_crawl
    response = await self.asyncRequester(url, session=session)
               ^^^^^^^^^^^^^^^^^^^^^^^^^^^^^^^^^^^^^^^^^^^^^^^
  File "/Users/yojunsmacbookprp/Documents/GitHub/PCSS/back/PCSS.py", line 422, in asyncRequester
    return await response.text()
           ^^^^^^^^^^^^^^^^^^^^^
  File "/Users/yojunsmacbookprp/Documents/GitHub/.venv/lib/python3.13/site-packages/aiohttp/client_reqrep.py", line 1260, in text
    await self.read()
  File "/Users/yojunsmacbookprp/Documents/GitHub/.venv/lib/python3.13/site-packages/aiohttp/client_reqrep.py", line 1218, in read
    self._body = await self.content.read()
                 ^^^^^^^^^^^^^^^^^^^^^^^^^
  File "/Users/yojunsmacbookprp/Documents/GitHub/.venv/lib/python3.13/site-packages/aiohttp/streams.py", line 418, in read
    block = await self.readany()
            ^^^^^^^^^^^^^^^^^^^^
  File "/Users/yojunsmacbookprp/Documents/GitHub/.venv/lib/python3.13/site-packages/aiohttp/streams.py", line 440, in readany
    await self._wait("readany")
  File "/Users/yojunsmacbookprp/Documents/GitHub/.venv/lib/python3.13/site-packages/aiohttp/streams.py", line 347, in _wait
    await waiter
asyncio.exceptions.CancelledError

[2025-01-23 15:39:14] Traceback (most recent call last):
  File "/Users/yojunsmacbookprp/Documents/GitHub/PCSS/back/PCSS.py", line 169, in MultiPaperCollector
    results = await asyncio.gather(*tasks)
              ^^^^^^^^^^^^^^^^^^^^^^^^^^^^
asyncio.exceptions.CancelledError

[2025-01-23 15:39:14] Traceback (most recent call last):
  File "/Users/yojunsmacbookprp/Documents/GitHub/PCSS/back/PCSS.py", line 193, in MultiConfCollector
    await asyncio.gather(*tasks)
asyncio.exceptions.CancelledError

